Workbook

Sheet README
A1: 손님 대사 자동생성 데이터베이스 (테스트용)
A3: 구조: 문장 = 뼈대(Template) + 키워드(Keyword) + 말투(Persona). 뼈대의 {슬롯}을 말투/키워드 값으로 치환해서 문장을 만든다.
A4: 말투는 손님마다 랜덤으로 1개 고른다. 한 손님의 대사는 전부 같은 말투를 쓴다.
A6: 시트 설명
A7: Persona : 말투 프로필. 한 행 = 말투 하나. 수량어 3단계와 동사 슬롯별 종결어미를 적는다.
A8: Template : 문장 뼈대. 재료 × 수량마다 여러 행 가능. 말투에 상관없는 부분만 쓰고 나머지는 {슬롯}으로 남긴다.
A9: Keyword : 재료/라멘 이름 동의어. 한 행 = 이름 하나. 같은 enum에 여러 행을 두면 랜덤 치환 대상이 된다.
A10: Preview : 노란 셀을 골라 조합 결과를 확인하는 테스트 시트. 수식은 건드리지 않는다.
A12: 슬롯 목록 (뼈대에 쓰는 토큰)
A13: {ing} 재료 이름 <- Keyword 시트
A14: {ramen} 라멘 이름 <- Keyword 시트
A15: {amt} 수량어 (1~3단계) <- Persona 시트 amt1/amt2/amt3
... A28: 범례: 노란 셀 = 사용자가 고르는 입력 / 파란 글씨 = 직접 적는 데이터 / 검은 글씨 = 수식

Sheet Persona
A1: personaId | B1: 이름 | C1: amt1 (조금) | D1: amt2 (많이) | E1: amt3 (아주 많이) | F1: give (넣어주세요) | G1: make (해주세요) | H1: want (싶어요) | I1: order (하나 주세요) | J1: prefix (첫마디) | K1: 특징 메모
A2: Polite | B2: 예의 바른 손님 | C2: 조금 | D2: 많이 | E2: 듬뿍 | F2: 넣어주세요 | G2: 해주세요 | H2: 싶어요 | I2: 하나 주세요 | J2: 저기요, | K2: 기본 해요체. 기존 DialogueGenerator 문장과 동일
A3: Formal | B3: 격식체 손님 | C3: 조금 | D3: 넉넉히 | E3: 충분히 | F3: 넣어주시겠습니까 | G3: 해주시겠습니까 | H3: 싶습니다 | I3: 하나 부탁드립니다 | J3: 실례합니다, | K3: 합쇼체. 비즈니스 톤
A4: Gyeongsang | B4: 경상도 손님 | C4: 쪼매 | D4: 마이 | E4: 억수로 | F4: 넣어주이소 | G4: 해주이소 | H4: 싶은데예 | I4: 하나 주이소 | J4: 사장님예, | K4: 경상도 사투리 존댓말
A5: Chungcheong | B5: 충청도 손님 | C5: 쪼끔 | D5: 많이 | E5: 겁나 | F5: 넣어주셔유 | G5: 해주셔유 | H5: 싶어유 | I5: 하나 주셔유 | J5: 저기유, | K5: 충청도 사투리. 느긋한 톤
A6: Otaku | B6: 오타쿠 손님 | C6: 약간 | D6: 제법 | E6: 풀파워로 | F6: 넣어주셨으면 합니다만 | G6: 해주셨으면 합니다만 | H6: 싶은 것입니다만 | I6: 하나 부탁드립니다만 | J6: 저, 실례합니다만, | K6: ~합니다만..? 어미. 말끝 흐림
A7: Military | B7: 군인 손님 | C7: 소량 | D7: 다량 | E7: 최대치로 | F7: 넣어주십시오 | G7: 해주십시오 | H7: 싶습니다 | I7: 하나 부탁드립니다 | J7: 안녕하십니까! | K7: 다나까체. 짧고 단호
A8: Sageuk | B8: 사극 말투 손님 | C8: 조금 | D8: 넉넉히 | E8: 듬뿍 | F8: 넣어주시오 | G8: 해주시오 | H8: 싶소 | I8: 하나 주시오 | J8: 여보게 주인장, | K8: 하오체

Sheet Template
A1: key (수식) | B1: ingredient | C1: amount | D1: idx | E1: template (뼈대) | F1: 비고
A2: =B2&"_"&C2&"_"&D2 -> Chashu_1_1 | B2: Chashu | C2: 1 | D2: 1 | E2: {ing} {amt} 더 {give}. | F2: 기존
A3: =B3&"_"&C3&"_"&D3 -> Chashu_1_2 | B3: Chashu | C3: 1 | D3: 2 | E3: {ing} 한 점만 더 {give}.
A4: =B4&"_"&C4&"_"&D4 -> Chashu_2_1 | B4: Chashu | C4: 2 | D4: 1 | E4: {ing} {amt} {give}. | F4: 기존
A5: =B5&"_"&C5&"_"&D5 -> Chashu_2_2 | B5: Chashu | C5: 2 | D5: 2 | E5: {ing} 넉넉하게 {give}.
A6: =B6&"_"&C6&"_"&D6 -> Chashu_3_1 | B6: Chashu | C6: 3 | D6: 1 | E6: 고기 향을 {amt} 느끼고 {want}. | F6: 기존
A7: =B7&"_"&C7&"_"&D7 -> Chashu_3_2 | B7: Chashu | C7: 3 | D7: 2 | E7: {ing} 위주로 {amt} {give}.
A8: =B8&"_"&C8&"_"&D8 -> FlavorOil_1_1 | B8: FlavorOil | C8: 1 | D8: 1 | E8: {ing} {amt} 더 {give}. | F8: 기존
A9: =B9&"_"&C9&"_"&D9 -> FlavorOil_1_2 | B9: FlavorOil | C9: 1 | D9: 2 | E9: {ing} 살짝만 더 {give}.
A10: =B10&"_"&C10&"_"&D10 -> FlavorOil_2_1 | B10: FlavorOil | C10: 2 | D10: 1 | E10: {ing} 좀 더 {give}. | F10: 기존
A11: =B11&"_"&C11&"_"&D11 -> FlavorOil_2_2 | B11: FlavorOil | C11: 2 | D11: 2 | E11: {ing} 향 조금 더 진하게 {make}.
A12: =B12&"_"&C12&"_"&D12 -> FlavorOil_3_1 | B12: FlavorOil | C12: 3 | D12: 1 | E12: {ing} {amt} {give}. | F12: 기존
A13: =B13&"_"&C13&"_"&D13 -> FlavorOil_3_2 | B13: FlavorOil | C13: 3 | D13: 2 | E13: {ing} 향 {amt} 느끼고 {want}.
A14: =B14&"_"&C14&"_"&D14 -> ChiliPowder_1_1 | B14: ChiliPowder | C14: 1 | D14: 1 | E14: {amt} 맵게 {make}. | F14: 기존
A15: =B15&"_"&C15&"_"&D15 -> ChiliPowder_1_2 | B15: ChiliPowder | C15: 1 | D15: 2 | E15: {ing} {amt} 더 {give}.
A16: =B16&"_"&C16&"_"&D16 -> ChiliPowder_2_1 | B16: ChiliPowder | C16: 2 | D16: 1 | E16: 맵게 {make}. | F16: 기존
A17: =B17&"_"&C17&"_"&D17 -> ChiliPowder_2_2 | B17: ChiliPowder | C17: 2 | D17: 2 | E17: {ing} {amt} {give}.
A18: =B18&"_"&C18&"_"&D18 -> ChiliPowder_3_1 | B18: ChiliPowder | C18: 3 | D18: 1 | E18: 칼칼하게 {make}. | F18: 기존
A19: =B19&"_"&C19&"_"&D19 -> ChiliPowder_3_2 | B19: ChiliPowder | C19: 3 | D19: 2 | E19: 아주 맵게 먹고 {want}.
A20: =B20&"_"&C20&"_"&D20 -> Menma_1_1 | B20: Menma | C20: 1 | D20: 1 | E20: {ing} 있으면 하나만 {give}. | F20: 기존
A21: =B21&"_"&C21&"_"&D21 -> Menma_1_2 | B21: Menma | C21: 1 | D21: 2 | E21: {ing} {amt} 더 {give}.
A22: =B22&"_"&C22&"_"&D22 -> Menma_2_1 | B22: Menma | C22: 2 | D22: 1 | E22: {ing} {amt} {give}. | F22: 기존
A23: =B23&"_"&C23&"_"&D23 -> Menma_2_2 | B23: Menma | C23: 2 | D23: 2 | E23: {ing} 넉넉히 {give}.
A24: =B24&"_"&C24&"_"&D24 -> Menma_3_1 | B24: Menma | C24: 3 | D24: 1 | E24: {ing} {amt} {amt} {give}. | F24: 기존 (많이많이)
A25: =B25&"_"&C25&"_"&D25 -> Menma_3_2 | B25: Menma | C25: 3 | D25: 2 | E25: {ing} 아삭한 식감 {amt} 느끼고 {want}.
A26: =B26&"_"&C26&"_"&D26 -> GreenOnion_1_1 | B26: GreenOnion | C26: 1 | D26: 1 | E26: {ing} 살짝만 더 {give}. | F26: 기존
A27: =B27&"_"&C27&"_"&D27 -> GreenOnion_1_2 | B27: GreenOnion | C27: 1 | D27: 2 | E27: {ing} {amt} 더 {give}.
A28: =B28&"_"&C28&"_"&D28 -> GreenOnion_2_1 | B28: GreenOnion | C28: 2 | D28: 1 | E28: {ing} {amt} {give}. | F28: 기존
A29: =B29&"_"&C29&"_"&D29 -> GreenOnion_2_2 | B29: GreenOnion | C29: 2 | D29: 2 | E29: {ing} 향 진하게 {make}.
A30: =B30&"_"&C30&"_"&D30 -> Egg_1_1 | B30: Egg | C30: 1 | D30: 1 | E30: {ing} 하나 더 {give}. | F30: 기존
A31: =B31&"_"&C31&"_"&D31 -> Egg_1_2 | B31: Egg | C31: 1 | D31: 2 | E31: {ing} {amt} 더 {give}.
A32: =B32&"_"&C32&"_"&D32 -> Egg_2_1 | B32: Egg | C32: 2 | D32: 1 | E32: {ing} {amt} {give}. | F32: 기존
A33: =B33&"_"&C33&"_"&D33 -> Egg_2_2 | B33: Egg | C33: 2 | D33: 2 | E33: {ing} 두 개 {give}.
A34: =B34&"_"&C34&"_"&D34 -> Egg_3_1 | B34: Egg | C34: 3 | D34: 1 | E34: {ing} {amt} {amt} {give}. | F34: 기존 (많이많이)
A35: =B35&"_"&C35&"_"&D35 -> Egg_3_2 | B35: Egg | C35: 3 | D35: 2 | E35: {ing} 위주로 먹고 {want}.
A36: =B36&"_"&C36&"_"&D36 -> BeanSprout_1_1 | B36: BeanSprout | C36: 1 | D36: 1 | E36: {ing} {amt} 더 {give}. | F36: 기존
A37: =B37&"_"&C37&"_"&D37 -> BeanSprout_1_2 | B37: BeanSprout | C37: 1 | D37: 2 | E37: {ing} 한 줌만 더 {give}.
A38: =B38&"_"&C38&"_"&D38 -> BeanSprout_2_1 | B38: BeanSprout | C38: 2 | D38: 1 | E38: {ing} {amt} {give}. | F38: 기존
A39: =B39&"_"&C39&"_"&D39 -> BeanSprout_2_2 | B39: BeanSprout | C39: 2 | D39: 2 | E39: {ing} 아삭하게 {amt} {give}.
A40: =B40&"_"&C40&"_"&D40 -> BeanSprout_3_1 | B40: BeanSprout | C40: 3 | D40: 1 | E40: {ing} {amt} {amt} {give}. | F40: 기존 (많이많이)
...

Sheet Keyword
A1: key (수식) | B1: enum | C1: idx | D1: keyword (이름) | E1: 비고
A2: =B2&"_"&C2 -> Chashu_1 | B2: Chashu | C2: 1 | D2: 차슈
A3: =B3&"_"&C3 -> Chashu_2 | B3: Chashu | C3: 2 | D3: 고기
A4: =B4&"_"&C4 -> Menma_1 | B4: Menma | C4: 1 | D4: 멘마
A5: =B5&"_"&C5 -> Menma_2 | B5: Menma | C5: 2 | D5: 죽순
A6: =B6&"_"&C6 -> GreenOnion_1 | B6: GreenOnion | C6: 1 | D6: 파
A7: =B7&"_"&C7 -> GreenOnion_2 | B7: GreenOnion | C7: 2 | D7: 대파
A8: =B8&"_"&C8 -> Egg_1 | B8: Egg | C8: 1 | D8: 계란
A9: =B9&"_"&C9 -> Egg_2 | B9: Egg | C9: 2 | D9: 달걀
A10: =B10&"_"&C10 -> Nori_1 | B10: Nori | C10: 1 | D10: 김
A11: =B11&"_"&C11 -> BeanSprout_1 | B11: BeanSprout | C11: 1 | D11: 숙주
A12: =B12&"_"&C12 -> BeanSprout_2 | B12: BeanSprout | C12: 2 | D12: 숙주나물
A13: =B13&"_"&C13 -> WoodEar_1 | B13: WoodEar | C13: 1 | D13: 목이버섯
... A18: =B18&"_"&C18 -> ChiliPowder_2 | B18: ChiliPowder | C18: 2 | D18: 고추가루
A19: =B19&"_"&C19 -> Shio_1 | B19: Shio | C19: 1 | D19: 시오 라멘 | E19: 라멘
A20: =B20&"_"&C20 -> Shoyu_1 | B20: Shoyu | C20: 1 | D20: 쇼유 라멘 | E20: 라멘
A21: =B21&"_"&C21 -> Tonkotsu_1 | B21: Tonkotsu | C21: 1 | D21: 돈코츠 라멘 | E21: 라멘

Sheet Preview
A1: 조합 테스트 (노란 셀만 바꾸세요)
A3: 말투 (personaId) | B3: Gyeongsang
A4: 라멘 (enum) | B4: Shoyu
A5: 라멘 뼈대 idx | B5: 1
A6: 재료 (enum) | B6: Chashu
A7: 수량 (amount) | B7: 3
A8: 재료 뼈대 idx | B8: 1
A9: 재료 키워드 idx | B9: 1
A12: 중간값 (수식)
A13: prefix | B13: =INDEX(Persona!$J$2:$J$8,MATCH($B$3,Persona!$A$2:$A$8,0)) -> 사장님예,
A14: 라멘 뼈대 | B14: =INDEX(Template!$E$2:$E$55,MATCH("Ramen_0_"&$B$5,Template!$A$2:$A$55,0)) -> {ramen} {order}.
A15: 라멘 이름 | B15: =INDEX(Keyword!$D$2:$D$21,MATCH($B$4&"_1",Keyword!$A$2:$A$21,0)) -> 쇼유 라멘
A16: 재료 뼈대 | B16: =INDEX(Template!$E$2:$E$55,MATCH($B$6&"_"&$B$7&"_"&$B$8,Template!$A$2:$A$55,0)) -> 고기 향을 {amt} 느끼고 {want}.
A17: 재료 이름 | B17: =IFERROR(INDEX(Keyword!$D$2:$D$21,MATCH($B$6&"_"&$B$9,Keyword!$A$2:$A$21,0)),INDEX(Keyword!$D$2:$D$21,MATCH($B$6&"_1",Keyword!$A$2:$A$21,0))) -> 차슈
A18: amt | B18: =CHOOSE($B$7,INDEX(Persona!$C$2:$C$8,MATCH($B$3,Persona!$A$2:$A$8,0)),INDEX(Persona!$D$2:$D$8,MATCH($B$3,Persona!$A$2:$A$8,0)),INDEX(Persona!$E$2:$E$8,MATCH($B$3,Persona!$A$2:$A$8,0))) -> 억수로
A19: give / make / want / order | B19: =INDEX(Persona!$F$2:$F$8,MATCH($B$3,Persona!$A$2:$A$8,0))&" / "&INDEX(Persona!$G$2:$G$8,MATCH($B$3,Persona!$A$2:$A$8,0))&" / "&INDEX(Persona!$H$2:$H$8,MATCH($B$3,Persona!$A$2:$A$8,0))&" / "&INDEX(Persona!$I$2:$I$8,MATCH($B$3,Persona!$A$2:$A$8,0)) -> 넣어주이소 / 해주이소 / 싶은데예 / 하나 주이소
A22: 결과
A23: 라멘 문장 | B23: =SUBSTITUTE(SUBSTITUTE(SUBSTITUTE(SUBSTITUTE(SUBSTITUTE(SUBSTITUTE(SUBSTITUTE($B$14,"{ramen}",$B$15),"{ing}",$B$17),"{amt}",$B$18),"{give}",INDEX(Persona!$F$2:$F$8,MATCH($B$3,Persona!$A$2:$A$8,0))),"{make}",INDEX(Persona!$G$2:$G$8,MATCH($B$3,Persona!$A$2:$A$8,0))),"{want}",INDEX(Persona!$H$2:$H$8,MATCH($B$3,Persona!$A$2:$A$8,0))),"{order}",INDEX(Persona!$I$2:$I$8,MATCH($B$3,Persona!$A$2:$A$8,0))) -> 쇼유 라멘 하나 주이소.
A24: 재료 문장 | B24: =SUBSTITUTE(SUBSTITUTE(SUBSTITUTE(SUBSTITUTE(SUBSTITUTE(SUBSTITUTE(SUBSTITUTE($B$16,"{ramen}",$B$15),"{ing}",$B$17),"{amt}",$B$18),"{give}",INDEX(Persona!$F$2:$F$8,MATCH($B$3,Persona!$A$2:$A$8,0))),"{make}",INDEX(Persona!$G$2:$G$8,MATCH($B$3,Persona!$A$2:$A$8,0))),"{want}",INDEX(Persona!$H$2:$H$8,MATCH($B$3,Persona!$A$2:$A$8,0))),"{order}",INDEX(Persona!$I$2:$I$8,MATCH($B$3,Persona!$A$2:$A$8,0))) -> 고기 향을 억수로 느끼고 싶은데예.
A25: 전체 대사 | B25: =$B$13&" "&$B$23&CHAR(10)&$B$24 -> 사장님예, 쇼유 라멘 하나 주이소. 고기 향을 억수로 느끼고 싶은데예.
